Workbook

Sheet Controle de NF - SETEMBRO
B1: 21.515.602/0001-51
A2: Mês | B2: CNPJ | C2: Fornecedor | D2: Gestor Adm | E2: NF | F2: Emissão da NF | G2: Valor da NF | H2: Conferência | I2: Observação | J2: SLA
A3: 45910 | B3: 01609514000101 | C3: =VLOOKUP(B3,Fornecedores!A:B,2,0) -> E-HUNTER TECNOLOGIA DA INFORMAÇÃO LTDA | D3: Sunara | E3: 00005513 | F3: 45901 | G3: 2614 | H3: =VLOOKUP(E3&B3,'Conf Oracle'!A:F,6,0) -> 45926.573 | J3: =IF(OR(ISBLANK(F3), ISBLANK(H3)), "", IFERROR(NETWORKDAYS(F3, H3), "")) -> 20
A4: 45910 | B4: 23412247000110 | C4: =VLOOKUP(B4,Fornecedores!A:B,2,0) -> AMAZON AWS SERVICOS BRASIL LTDA | D4: Ingrid | E4: 91696365 | F4: 45901 | G4: 114905.83 | H4: =VLOOKUP(E4&B4,'Conf Oracle'!A:F,6,0) -> #N/A | I4: Invoice NFs 04729432 e 04729425 | J4: =IF(OR(ISBLANK(F4), ISBLANK(H4)), "", IFERROR(NETWORKDAYS(F4, H4), ""))
A5: 45910 | B5: 09162855000517 | C5: =VLOOKUP(B5,Fornecedores!A:B,2,0) -> PTLS SERV TECNOLOGIA E ASSESS TECN LTDA | D5: Sunara | E5: 00219477 | F5: 45901 | G5: 30803.59 | H5: =VLOOKUP(E5&B5,'Conf Oracle'!A:F,6,0) -> 45915.691 | J5: =IF(OR(ISBLANK(F5), ISBLANK(H5)), "", IFERROR(NETWORKDAYS(F5, H5), "")) -> 11
A6: 45910 | B6: 02279806000196 | C6: =VLOOKUP(B6,Fornecedores!A:B,2,0) -> DAIMON ENGENHARIA E SISTEMAS S/S LTDA | D6: Sunara | E6: 00005097 | F6: 45902 | G6: 18982.5 | H6: =VLOOKUP(E6&B6,'Conf Oracle'!A:F,6,0) -> 45911.671 | J6: =IF(OR(ISBLANK(F6), ISBLANK(H6)), "", IFERROR(NETWORKDAYS(F6, H6), "")) -> 8
A7: 45910 | B7: 13617051000109 | C7: =VLOOKUP(B7,Fornecedores!A:B,2,0) -> COMPLEMENTO CONSULTORIA E TECNOLOGIA LTDA | D7: Sunara | E7: 00000500 | F7: 45903 | G7: 9600 | H7: =VLOOKUP(E7&B7,'Conf Oracle'!A:F,6,0) -> 45911.362 | J7: =IF(OR(ISBLANK(F7), ISBLANK(H7)), "", IFERROR(NETWORKDAYS(F7, H7), "")) -> 7
A8: 45910 | B8: 33541368000116 | C8: =VLOOKUP(B8,Fornecedores!A:B,2,0) -> CIA HIDRO ELETRICA SAO FRANCISCO - CHESF | D8: Sunara | E8: 00044496 | F8: 45903 | G8: 4011.82 | H8: =VLOOKUP(E8&B8,'Conf Oracle'!A:F,6,0) -> #N/A | I8: OC_0011253 - LANÇADA | J8: =IF(OR(ISBLANK(F8), ISBLANK(H8)), "", IFERROR(NETWORKDAYS(F8, H8), ""))
A9: 45910 | B9: 82703331000152 | C9: =VLOOKUP(B9,Fornecedores!A:B,2,0) -> MRTS CONSULTORIA E ENGENHARIA LTDA ME | D9: Sunara | E9: 00001310 | F9: 45909 | G9: 18982.5 | H9: =VLOOKUP(E9&B9,'Conf Oracle'!A:F,6,0) -> 45916.665 | J9: =IF(OR(ISBLANK(F9), ISBLANK(H9)), "", IFERROR(NETWORKDAYS(F9, H9), "")) -> 6
A10: 45910 | B10: 82703331000152 | C10: =VLOOKUP(B10,Fornecedores!A:B,2,0) -> MRTS CONSULTORIA E ENGENHARIA LTDA ME | D10: Sunara | E10: 00001311 | F10: 45909 | G10: 18982.5 | H10: =VLOOKUP(E10&B10,'Conf Oracle'!A:F,6,0) -> 45916.673 | J10: =IF(OR(ISBLANK(F10), ISBLANK(H10)), "", IFERROR(NETWORKDAYS(F10, H10), "")) -> 6
A11: 45910 | B11: 05217065000107 | C11: =VLOOKUP(B11,Fornecedores!A:B,2,0) -> ARVP CONSULTORIA E CAPACITACAO LTDA | D11: Pedro | E11: 00001083 | F11: 45901 | G11: 38410.07 | H11: =VLOOKUP(E11&B11,'Conf Oracle'!A:F,6,0) -> 45918.676 | J11: =IF(OR(ISBLANK(F11), ISBLANK(H11)), "", IFERROR(NETWORKDAYS(F11, H11), "")) -> 14
A12: 45910 | B12: 81785545000152 | C12: =VLOOKUP(B12,Fornecedores!A:B,2,0) -> DEL GRANDE INFO E TELEC IND E COM LTDA | D12: Pedro | E12: 00004449 | F12: 45901 | G12: 3151.24 | H12: =VLOOKUP(E12&B12,'Conf Oracle'!A:F,6,0) -> 45918.666 | J12: =IF(OR(ISBLANK(F12), ISBLANK(H12)), "", IFERROR(NETWORKDAYS(F12, H12), "")) -> 14
A13: 45910 | B13: 81785545000152 | C13: =VLOOKUP(B13,Fornecedores!A:B,2,0) -> DEL GRANDE INFO E TELEC IND E COM LTDA | D13: Pedro | E13: 00004448 | F13: 45901 | G13: 1618.7 | H13: =VLOOKUP(E13&B13,'Conf Oracle'!A:F,6,0) -> 45918.675 | J13: =IF(OR(ISBLANK(F13), ISBLANK(H13)), "", IFERROR(NETWORKDAYS(F13, H13), "")) -> 14
A14: 45910 | B14: 81785545000152 | C14: =VLOOKUP(B14,Fornecedores!A:B,2,0) -> DEL GRANDE INFO E TELEC IND E COM LTDA | D14: Pedro | E14: 00004447 | F14: 45901 | G14: 5077 | H14: =VLOOKUP(E14&B14,'Conf Oracle'!A:F,6,0) -> 45918.671 | J14: =IF(OR(ISBLANK(F14), ISBLANK(H14)), "", IFERROR(NETWORKDAYS(F14, H14), "")) -> 14
A15: 45910 | B15: 81785545000152 | C15: =VLOOKUP(B15,Fornecedores!A:B,2,0) -> DEL GRANDE INFO E TELEC IND E COM LTDA | D15: Pedro | E15: 00004450 | F15: 45901 | G15: 2825.73 | H15: =VLOOKUP(E15&B15,'Conf Oracle'!A:F,6,0) -> 45918.661 | J15: =IF(OR(ISBLANK(F15), ISBLANK(H15)), "", IFERROR(NETWORKDAYS(F15, H15), "")) -> 14
A16: 45910 | B16: 82895327000133 | C16: =VLOOKUP(B16,Fornecedores!A:B,2,0) -> FUNDACAO DE ENSINO E ENGENHARIA DE SC | D16: Pedro | E16: 00009699 | F16: 45902 | G16: 53333.33 | H16: =VLOOKUP(E16&B16,'Conf Oracle'!A:F,6,0) -> 45918.693 | J16: =IF(OR(ISBLANK(F16), ISBLANK(H16)), "", IFERROR(NETWORKDAYS(F16, H16), "")) -> 13
A17: 45910 | B17: 04732840000108 | C17: =VLOOKUP(B17,Fornecedores!A:B,2,0) -> CONCERT TECHNOLOGIES S.A. | D17: Pedro | E17: 00003247 | F17: 45903 | G17: 60000 | H17: =VLOOKUP(E17&B17,'Conf Oracle'!A:F,6,0) -> 45918.68 | J17: =IF(OR(ISBLANK(F17), ISBLANK(H17)), "", IFERROR(NETWORKDAYS(F17, H17), "")) -> 12
A18: 45910 | B18: 30608514000195 | C18: =VLOOKUP(B18,Fornecedores!A:B,2,0) -> AGENCIA FR DE COMUNICACAO LTDA | D18: Pedro | E18: 00004493 | F18: 45904 | G18: 39746.37 | H18: =VLOOKUP(E18&B18,'Conf Oracle'!A:F,6,0) -> #N/A | J18: =IF(OR(ISBLANK(F18), ISBLANK(H18)), "", IFERROR(NETWORKDAYS(F18, H18), ""))
A19: 45910 | B19: 10791466000106 | C19: =VLOOKUP(B19,Fornecedores!A:B,2,0) -> RPT.ESTRATEGIA CONSULTORIA LTDA | D19: Pedro | E19: 00001129 | F19: 45908 | G19: 11250 | H19: =VLOOKUP(E19&B19,'Conf Oracle'!A:F,6,0) -> #N/A | J19: =IF(OR(ISBLANK(F19), ISBLANK(H19)), "", IFERROR(NETWORKDAYS(F19, H19), ""))
A20: 45910 | B20: 42288886000160 | C20: =VLOOKUP(B20,Fornecedores!A:B,2,0) -> CENTRO DE PESQUISA DE ENERGIA ELET CEPEL | D20: Pedro | E20: 00017311 | F20: 45909 | G20: 117356.88 | H20: =VLOOKUP(E20&B20,'Conf Oracle'!A:F,6,0) -> #N/A | J20: =IF(OR(ISBLANK(F20), ISBLANK(H20)), "", IFERROR(NETWORKDAYS(F20, H20), ""))
... A24: 45911 | B24: 42288886000160 | C24: =VLOOKUP(B24,Fornecedores!A:B,2,0) -> CENTRO DE PESQUISA DE ENERGIA ELET CEPEL | D24: Pedro | E24: 00017314 | F24: 45909 | G24: 55700 | H24: =VLOOKUP(E24&B24,'Conf Oracle'!A:F,6,0) -> #N/A | J24: =IF(OR(ISBLANK(F24), ISBLANK(H24)), "", IFERROR(NETWORKDAYS(F24, H24), ""))
A25: 45911 | B25: 15667402000111 | C25: =VLOOKUP(B25,Fornecedores!A:B,2,0) -> SIMPLE ENERGY ASSESSORIA E GESTAO DE ENERGIA LTDA. | D25: Evandrea | E25: 00022639 | F25: 45902 | G25: 733.38 | H25: =VLOOKUP(E25&B25,'Conf Oracle'!A:F,6,0) -> 45919.386 | I25: lançada | J25: =IF(OR(ISBLANK(F25), ISBLANK(H25)), "", IFERROR(NETWORKDAYS(F25, H25), "")) -> 14
A26: 45911 | B26: 15667402000111 | C26: =VLOOKUP(B26,Fornecedores!A:B,2,0) -> SIMPLE ENERGY ASSESSORIA E GESTAO DE ENERGIA LTDA. | D26: Evandrea | E26: 00022643 | F26: 45902 | G26: 733.38 | H26: =VLOOKUP(E26&B26,'Conf Oracle'!A:F,6,0) -> 45919.407 | I26: lançada | J26: =IF(OR(ISBLANK(F26), ISBLANK(H26)), "", IFERROR(NETWORKDAYS(F26, H26), "")) -> 14
A27: 45911 | B27: 15667402000111 | C27: =VLOOKUP(B27,Fornecedores!A:B,2,0) -> SIMPLE ENERGY ASSESSORIA E GESTAO DE ENERGIA LTDA. | D27: Evandrea | E27: 00022646 | F27: 45902 | G27: 733.38 | H27: =VLOOKUP(E27&B27,'Conf Oracle'!A:F,6,0) -> 45919.402 | I27: lançada | J27: =IF(OR(ISBLANK(F27), ISBLANK(H27)), "", IFERROR(NETWORKDAYS(F27, H27), "")) -> 14
A28: 45911 | B28: 15667402000111 | C28: =VLOOKUP(B28,Fornecedores!A:B,2,0) -> SIMPLE ENERGY ASSESSORIA E GESTAO DE ENERGIA LTDA. | D28: Evandrea | E28: 00022645 | F28: 45902 | G28: 733.38 | H28: =VLOOKUP(E28&B28,'Conf Oracle'!A:F,6,0) -> 45919.633 | I28: lançada | J28: =IF(OR(ISBLANK(F28), ISBLANK(H28)), "", IFERROR(NETWORKDAYS(F28, H28), "")) -> 14
A29: 45911 | B29: 00001180000126 | C29: =VLOOKUP(B29,Fornecedores!A:B,2,0) -> Centrais Elétricas Brasileiras S/A - Eletrobras | D29: Evandrea | E29: 00059757 | F29: 45903 | G29: 18749.39 | H29: =VLOOKUP(E29&B29,'Conf Oracle'!A:F,6,0) -> 45908.579 | J29: =IF(OR(ISBLANK(F29), ISBLANK(H29)), "", IFERROR(NETWORKDAYS(F29, H29), "")) -> 4
A30: 45911 | B30: 00001180000126 | C30: =VLOOKUP(B30,Fornecedores!A:B,2,0) -> Centrais Elétricas Brasileiras S/A - Eletrobras | D30: Evandrea | E30: 00059755 | F30: 45903 | G30: 85391.74 | H30: =VLOOKUP(E30&B30,'Conf Oracle'!A:F,6,0) -> 45908.561 | J30: =IF(OR(ISBLANK(F30), ISBLANK(H30)), "", IFERROR(NETWORKDAYS(F30, H30), "")) -> 4
A31: 45911 | B31: 00001180000126 | C31: =VLOOKUP(B31,Fornecedores!A:B,2,0) -> Centrais Elétricas Brasileiras S/A - Eletrobras | D31: Evandrea | E31: 00059754 | F31: 45903 | G31: 59329.76 | H31: =VLOOKUP(E31&B31,'Conf Oracle'!A:F,6,0) -> 45908.552 | J31: =IF(OR(ISBLANK(F31), ISBLANK(H31)), "", IFERROR(NETWORKDAYS(F31, H31), "")) -> 4
A32: 45911 | B32: 00001180000126 | C32: =VLOOKUP(B32,Fornecedores!A:B,2,0) -> Centrais Elétricas Brasileiras S/A - Eletrobras | D32: Evandrea | E32: 00059756 | F32: 45903 | G32: 36415.67 | H32: =VLOOKUP(E32&B32,'Conf Oracle'!A:F,6,0) -> 45908.566 | J32: =IF(OR(ISBLANK(F32), ISBLANK(H32)), "", IFERROR(NETWORKDAYS(F32, H32), "")) -> 4
A33: 45911 | B33: 60444437000146 | C33: =VLOOKUP(B33,Fornecedores!A:B,2,0) -> LIGHT SERV. DE ELETRICIDADE SA | D33: Evandrea | E33: 00292749 | F33: 45901 | G33: 140022.94 | H33: =VLOOKUP(E33&B33,'Conf Oracle'!A:F,6,0) -> #N/A | I33: Lançada | J33: =IF(OR(ISBLANK(F33), ISBLANK(H33)), "", IFERROR(NETWORKDAYS(F33, H33), ""))
A34: 45911 | B34: 57623555000107 | C34: =VLOOKUP(B34,Fornecedores!A:B,2,0) -> MAGICCOMP ENG E SERV DE INFORMATICA LTDA | D34: Jessy | E34: 00055887 | F34: 45901 | G34: 49705.57 | H34: =VLOOKUP(E34&B34,'Conf Oracle'!A:F,6,0) -> #N/A | I34: OC_0011447- NF 00055887 substituida para 55955 | J34: =IF(OR(ISBLANK(F34), ISBLANK(H34)), "", IFERROR(NETWORKDAYS(F34, H34), ""))
A35: 45911 | B35: 57623555000107 | C35: =VLOOKUP(B35,Fornecedores!A:B,2,0) -> MAGICCOMP ENG E SERV DE INFORMATICA LTDA | D35: Jessy | E35: 00055888 | F35: 45901 | G35: 49705.57 | H35: =VLOOKUP(E35&B35,'Conf Oracle'!A:F,6,0) -> 45918.449 | I35: OC_0011332 | J35: =IF(OR(ISBLANK(F35), ISBLANK(H35)), "", IFERROR(NETWORKDAYS(F35, H35), "")) -> 14
A36: 45911 | B36: 57623555000107 | C36: =VLOOKUP(B36,Fornecedores!A:B,2,0) -> MAGICCOMP ENG E SERV DE INFORMATICA LTDA | D36: Jessy | E36: 00055889 | F36: 45901 | G36: 72500 | H36: =VLOOKUP(E36&B36,'Conf Oracle'!A:F,6,0) -> 45925.352 | I36: OC_0011452 | J36: =IF(OR(ISBLANK(F36), ISBLANK(H36)), "", IFERROR(NETWORKDAYS(F36, H36), "")) -> 19
A37: 45911 | B37: 57623555000107 | C37: =VLOOKUP(B37,Fornecedores!A:B,2,0) -> MAGICCOMP ENG E SERV DE INFORMATICA LTDA | D37: Jessy | E37: 00055882 | F37: 45901 | G37: 27750 | H37: =VLOOKUP(E37&B37,'Conf Oracle'!A:F,6,0) -> 45916.623 | I37: ok | J37: =IF(OR(ISBLANK(F37), ISBLANK(H37)), "", IFERROR(NETWORKDAYS(F37, H37), "")) -> 12
A38: 45911 | B38: 57623555000107 | C38: =VLOOKUP(B38,Fornecedores!A:B,2,0) -> MAGICCOMP ENG E SERV DE INFORMATICA LTDA | D38: Jessy | E38: 00055883 | F38: 45901 | G38: 27750 | H38: =VLOOKUP(E38&B38,'Conf Oracle'!A:F,6,0) -> 45916.647 | I38: ok | J38: =IF(OR(ISBLANK(F38), ISBLANK(H38)), "", IFERROR(NETWORKDAYS(F38, H38), "")) -> 12
A39: 45911 | B39: 57623555000107 | C39: =VLOOKUP(B39,Fornecedores!A:B,2,0) -> MAGICCOMP ENG E SERV DE INFORMATICA LTDA | D39: Jessy | E39: 00055884 | F39: 45901 | G39: 27750 | H39: =VLOOKUP(E39&B39,'Conf Oracle'!A:F,6,0) -> 45916.649 | I39: ok | J39: =IF(OR(ISBLANK(F39), ISBLANK(H39)), "", IFERROR(NETWORKDAYS(F39, H39), "")) -> 12
A40: 45911 | B40: 57623555000107 | C40: =VLOOKUP(B40,Fornecedores!A:B,2,0) -> MAGICCOMP ENG E SERV DE INFORMATICA LTDA | D40: Jessy | E40: 00055885 | F40: 45901 | G40: 27750 | H40: =VLOOKUP(E40&B40,'Conf Oracle'!A:F,6,0) -> 45916.644 | I40: ok | J40: =IF(OR(ISBLANK(F40), ISBLANK(H40)), "", IFERROR(NETWORKDAYS(F40, H40), "")) -> 12
A41: 45911 | B41: 21356354000143 | C41: =VLOOKUP(B41,Fornecedores!A:B,2,0) -> POPULOS TECNOLOGIA LTDA | D41: Jessy | E41: 00003062 | F41: 45901 | G41: 3118.52 | H41: =VLOOKUP(E41&B41,'Conf Oracle'!A:F,6,0) -> 45915.657 | I41: ok | J41: =IF(OR(ISBLANK(F41), ISBLANK(H41)), "", IFERROR(NETWORKDAYS(F41, H41), "")) -> 11
A42: 45911 | B42: 51886784000138 | C42: =VLOOKUP(B42,Fornecedores!A:B,2,0) -> EASY 5 SOLUCOES LTDA | D42: Jessy | E42: 00000638 | F42: 45901 | G42: 20800 | H42: =VLOOKUP(E42&B42,'Conf Oracle'!A:F,6,0) -> 45916.422 | I42: ok | J42: =IF(OR(ISBLANK(F42), ISBLANK(H42)), "", IFERROR(NETWORKDAYS(F42, H42), "")) -> 12
A43: 45911 | B43: 51886784000138 | C43: =VLOOKUP(B43,Fornecedores!A:B,2,0) -> EASY 5 SOLUCOES LTDA | D43: Jessy | E43: 00000637 | F43: 45901 | G43: 20800 | H43: =VLOOKUP(E43&B43,'Conf Oracle'!A:F,6,0) -> 45916.43 | I43: ok | J43: =IF(OR(ISBLANK(F43), ISBLANK(H43)), "", IFERROR(NETWORKDAYS(F43, H43), "")) -> 12
...

Sheet Controle de NF - Março
A2: Mês | B2: CNPJ | C2: Fornecedor | D2: Gestor Adm | E2: NF | F2: Emissão da NF | G2: Valor da NF | H2: Conferência | I2: Observação | J2: SLA
A3: 45730 | B3: 15667402000111 | C3: =VLOOKUP(B3,Fornecedores!A:B,2,0) -> SIMPLE ENERGY ASSESSORIA E GESTAO DE ENERGIA LTDA. | D3: EVANDREA | E3: 00020196 | F3: 45719 | G3: 733.38 | H3: =VLOOKUP(E3&B3,'Conf Oracle'!A:F,6,0) -> 45742.481 | I3: Lançada | J3: =IF(OR(ISBLANK(F3), ISBLANK(H3)), "", IFERROR(NETWORKDAYS(F3, H3), "")) -> 18
A4: 45730 | B4: 15667402000111 | C4: =VLOOKUP(B4,Fornecedores!A:B,2,0) -> SIMPLE ENERGY ASSESSORIA E GESTAO DE ENERGIA LTDA. | D4: EVANDREA | E4: 00020214 | F4: 45719 | G4: 733.38 | H4: =VLOOKUP(E4&B4,'Conf Oracle'!A:F,6,0) -> 45742.392 | I4: FALTA LANÇAR | J4: =IF(OR(ISBLANK(F4), ISBLANK(H4)), "", IFERROR(NETWORKDAYS(F4, H4), "")) -> 18
A5: 45730 | B5: 15667402000111 | C5: =VLOOKUP(B5,Fornecedores!A:B,2,0) -> SIMPLE ENERGY ASSESSORIA E GESTAO DE ENERGIA LTDA. | D5: EVANDREA | E5: 00020200 | F5: 45719 | G5: 733.38 | H5: =VLOOKUP(E5&B5,'Conf Oracle'!A:F,6,0) -> 45742.486 | I5: Lançada | J5: =IF(OR(ISBLANK(F5), ISBLANK(H5)), "", IFERROR(NETWORKDAYS(F5, H5), "")) -> 18
A6: 45730 | B6: 16554325000156 | C6: =VLOOKUP(B6,Fornecedores!A:B,2,0) -> AMBIENTE VERDE RESIDUOS LTDA | D6: EVANDREA | E6: 00000807 | F6: 45719 | G6: 2690 | H6: =VLOOKUP(E6&B6,'Conf Oracle'!A:F,6,0) -> 45743.656 | I6: Lançada | J6: =IF(OR(ISBLANK(F6), ISBLANK(H6)), "", IFERROR(NETWORKDAYS(F6, H6), "")) -> 19
A7: 45734 | B7: 15667402000111 | C7: =VLOOKUP(B7,Fornecedores!A:B,2,0) -> SIMPLE ENERGY ASSESSORIA E GESTAO DE ENERGIA LTDA. | D7: EVANDREA | E7: 00020205 | F7: 45719 | G7: 733.38 | H7: =VLOOKUP(E7&B7,'Conf Oracle'!A:F,6,0) -> 45742.423 | I7: FALTA LANÇAR | J7: =IF(OR(ISBLANK(F7), ISBLANK(H7)), "", IFERROR(NETWORKDAYS(F7, H7), "")) -> 18
A8: 45734 | B8: 16554325000156 | C8: =VLOOKUP(B8,Fornecedores!A:B,2,0) -> AMBIENTE VERDE RESIDUOS LTDA | D8: EVANDREA | E8: 00000808 | F8: 45719 | G8: 2690 | H8: =VLOOKUP(E8&B8,'Conf Oracle'!A:F,6,0) -> 45743.667 | I8: Lançada | J8: =IF(OR(ISBLANK(F8), ISBLANK(H8)), "", IFERROR(NETWORKDAYS(F8, H8), "")) -> 19
A9: 45734 | B9: 16554325000156 | C9: =VLOOKUP(B9,Fornecedores!A:B,2,0) -> AMBIENTE VERDE RESIDUOS LTDA | D9: EVANDREA | E9: 00000813 | F9: 45719 | G9: 2490 | H9: =VLOOKUP(E9&B9,'Conf Oracle'!A:F,6,0) -> 45743.681 | I9: Lançada | J9: =IF(OR(ISBLANK(F9), ISBLANK(H9)), "", IFERROR(NETWORKDAYS(F9, H9), "")) -> 19
A10: 45734 | B10: 33597659001602 | C10: =VLOOKUP(B10,Fornecedores!A:B,2,0) -> RICOH BRASIL S A | D10: EVANDREA | E10: 00049486 | F10: 45722 | G10: 1287.36 | H10: =VLOOKUP(E10&B10,'Conf Oracle'!A:F,6,0) -> 45744.725 | I10: Lançada | J10: =IF(OR(ISBLANK(F10), ISBLANK(H10)), "", IFERROR(NETWORKDAYS(F10, H10), "")) -> 17
A11: 45734 | B11: 33597659000126 | C11: =VLOOKUP(B11,Fornecedores!A:B,2,0) -> RICOH BRASIL S A | D11: EVANDREA | E11: 00049487 | F11: 45722 | G11: 80.32 | H11: =VLOOKUP(E11&B11,'Conf Oracle'!A:F,6,0) -> 45744.47 | I11: Lançada | J11: =IF(OR(ISBLANK(F11), ISBLANK(H11)), "", IFERROR(NETWORKDAYS(F11, H11), "")) -> 17
A12: 45734 | B12: 33597659000126 | C12: =VLOOKUP(B12,Fornecedores!A:B,2,0) -> RICOH BRASIL S A | D12: EVANDREA | E12: 00049488 | F12: 45722 | G12: 254.17 | H12: =VLOOKUP(E12&B12,'Conf Oracle'!A:F,6,0) -> 45747.368 | I12: Lançada | J12: =IF(OR(ISBLANK(F12), ISBLANK(H12)), "", IFERROR(NETWORKDAYS(F12, H12), "")) -> 18
A13: 45734 | B13: 33597659000126 | C13: =VLOOKUP(B13,Fornecedores!A:B,2,0) -> RICOH BRASIL S A | D13: EVANDREA | E13: 00049489 | F13: 45722 | G13: 86.56 | H13: =VLOOKUP(E13&B13,'Conf Oracle'!A:F,6,0) -> 45744.731 | I13: Lançada | J13: =IF(OR(ISBLANK(F13), ISBLANK(H13)), "", IFERROR(NETWORKDAYS(F13, H13), "")) -> 17
A14: 45734 | B14: 33597659001602 | C14: =VLOOKUP(B14,Fornecedores!A:B,2,0) -> RICOH BRASIL S A | D14: EVANDREA | E14: 00049491 | F14: 45722 | G14: 253.64 | H14: =VLOOKUP(E14&B14,'Conf Oracle'!A:F,6,0) -> 45744.718 | I14: Lançada | J14: =IF(OR(ISBLANK(F14), ISBLANK(H14)), "", IFERROR(NETWORKDAYS(F14, H14), "")) -> 17
... A16: 45734 | B16: 00028986001694 | C16: =VLOOKUP(B16,Fornecedores!A:B,2,0) -> ELEVADORES ATLAS SCHINDLER SA | D16: EVANDREA | E16: 00465236 | F16: 45721 | G16: 1960.94 | H16: =VLOOKUP(E16&B16,'Conf Oracle'!A:F,6,0) -> 45736.701 | I16: Lançada | J16: =IF(OR(ISBLANK(F16), ISBLANK(H16)), "", IFERROR(NETWORKDAYS(F16, H16), "")) -> 12
A17: 45734 | B17: 08270682000164 | C17: =VLOOKUP(B17,Fornecedores!A:B,2,0) -> CONFIDERE IMOBILIARIA LTDA | D17: EVANDREA | E17: 00202503 | F17: 45722 | G17: 2737093.3 | H17: =VLOOKUP(E17&B17,'Conf Oracle'!A:F,6,0) -> 45727.389 | J17: =IF(OR(ISBLANK(F17), ISBLANK(H17)), "", IFERROR(NETWORKDAYS(F17, H17), "")) -> 4
A18: 45734 | B18: 05208211001614 | C18: =VLOOKUP(B18,Fornecedores!A:B,2,0) -> IN-HAUS INDUSTRIAL E SERVICOS DE LOGISTICA LTDA | D18: EVANDREA | E18: 00000365 | F18: 45723 | G18: 94387.81 | H18: =VLOOKUP(E18&B18,'Conf Oracle'!A:F,6,0) -> 45744.702 | I18: FALTA LANÇAR | J18: =IF(OR(ISBLANK(F18), ISBLANK(H18)), "", IFERROR(NETWORKDAYS(F18, H18), "")) -> 16
A19: 45734 | B19: 00973749000115 | C19: =VLOOKUP(B19,Fornecedores!A:B,2,0) -> TOP SERVICE SERVICOS E SISTEMAS S/A | D19: EVANDREA | E19: 00212863 | F19: 45723 | G19: 10427.67 | H19: =VLOOKUP(E19&B19,'Conf Oracle'!A:F,6,0) -> 45744.406 | I19: FALTA LANÇAR | J19: =IF(OR(ISBLANK(F19), ISBLANK(H19)), "", IFERROR(NETWORKDAYS(F19, H19), "")) -> 16
A20: 45734 | B20: 00973749000115 | C20: =VLOOKUP(B20,Fornecedores!A:B,2,0) -> TOP SERVICE SERVICOS E SISTEMAS S/A | D20: EVANDREA | E20: 00212844 | F20: 45723 | G20: 49388.6 | H20: =VLOOKUP(E20&B20,'Conf Oracle'!A:F,6,0) -> 45744.429 | I20: FALTA LANÇAR | J20: =IF(OR(ISBLANK(F20), ISBLANK(H20)), "", IFERROR(NETWORKDAYS(F20, H20), "")) -> 16
A21: 45734 | B21: 90347840005691 | C21: =VLOOKUP(B21,Fornecedores!A:B,2,0) -> TK ELEVADORES BRASIL LTDA. | D21: EVANDREA | E21: 00111731 | F21: 45717 | G21: 13781.17 | H21: =VLOOKUP(E21&B21,'Conf Oracle'!A:F,6,0) -> 45736.383 | I21: FALTA LANÇAR | J21: =IF(OR(ISBLANK(F21), ISBLANK(H21)), "", IFERROR(NETWORKDAYS(F21, H21), "")) -> 14
A22: 45734 | B22: 40432544000147 | C22: =VLOOKUP(B22,Fornecedores!A:B,2,0) -> CLARO SA | D22: EVANDREA | E22: 83906243 | F22: 45726 | G22: 18299.85 | H22: =VLOOKUP(E22&B22,'Conf Oracle'!A:F,6,0) -> 45735.614 | I22: Lançada | J22: =IF(OR(ISBLANK(F22), ISBLANK(H22)), "", IFERROR(NETWORKDAYS(F22, H22), "")) -> 8
A23: 45734 | B23: 40432544000147 | C23: =VLOOKUP(B23,Fornecedores!A:B,2,0) -> CLARO SA | D23: EVANDREA | E23: 05393221 | F23: 45726 | G23: 2419.83 | H23: =VLOOKUP(E23&B23,'Conf Oracle'!A:F,6,0) -> 45735.611 | I23: Lançada | J23: =IF(OR(ISBLANK(F23), ISBLANK(H23)), "", IFERROR(NETWORKDAYS(F23, H23), "")) -> 8
A24: 45734 | B24: 40432544000147 | C24: =VLOOKUP(B24,Fornecedores!A:B,2,0) -> CLARO SA | D24: EVANDREA | E24: 91614197 | F24: 45726 | G24: 1843.58 | H24: =VLOOKUP(E24&B24,'Conf Oracle'!A:F,6,0) -> 45735.607 | I24: Lançada | J24: =IF(OR(ISBLANK(F24), ISBLANK(H24)), "", IFERROR(NETWORKDAYS(F24, H24), "")) -> 8
A25: 45734 | B25: 40432544000147 | C25: =VLOOKUP(B25,Fornecedores!A:B,2,0) -> CLARO SA | D25: EVANDREA | E25: 31199179 | F25: 45726 | G25: 3543.94 | H25: =VLOOKUP(E25&B25,'Conf Oracle'!A:F,6,0) -> 45735.603 | I25: Lançada | J25: =IF(OR(ISBLANK(F25), ISBLANK(H25)), "", IFERROR(NETWORKDAYS(F25, H25), "")) -> 8
A26: 45734 | B26: 40432544000147 | C26: =VLOOKUP(B26,Fornecedores!A:B,2,0) -> CLARO SA | D26: EVANDREA | E26: 00737742 | F26: 45726 | G26: 1949.23 | H26: =VLOOKUP(E26&B26,'Conf Oracle'!A:F,6,0) -> 45735.598 | I26: Lançada | J26: =IF(OR(ISBLANK(F26), ISBLANK(H26)), "", IFERROR(NETWORKDAYS(F26, H26), "")) -> 8
A27: 45734 | B27: 13498242000107 | C27: =VLOOKUP(B27,Fornecedores!A:B,2,0) -> GCCENTRO ESPECIALI EM SERV DE LIMP LTDA | D27: EVANDREA | E27: 00005900 | F27: 45727 | G27: 8306.01 | H27: =VLOOKUP(E27&B27,'Conf Oracle'!A:F,6,0) -> 45747.767 | I27: FALTA LANÇAR | J27: =IF(OR(ISBLANK(F27), ISBLANK(H27)), "", IFERROR(NETWORKDAYS(F27, H27), "")) -> 15
A28: 45734 | B28: 16554325000156 | C28: =VLOOKUP(B28,Fornecedores!A:B,2,0) -> AMBIENTE VERDE RESIDUOS LTDA | D28: EVANDREA | E28: 00000837 | F28: 45728 | G28: 6624.55 | H28: =VLOOKUP(E28&B28,'Conf Oracle'!A:F,6,0) -> 45747.608 | I28: FALTA LANÇAR | J28: =IF(OR(ISBLANK(F28), ISBLANK(H28)), "", IFERROR(NETWORKDAYS(F28, H28), "")) -> 14
A29: 45734 | B29: 29650979000125 | C29: =VLOOKUP(B29,Fornecedores!A:B,2,0) -> CAPACITARE RECURSOS HUMANOS EIRELI | D29: EVANDREA | E29: 00002205 | F29: 45726 | G29: 14880 | H29: =VLOOKUP(E29&B29,'Conf Oracle'!A:F,6,0) -> 45748.614 | I29: Lançada | J29: =IF(OR(ISBLANK(F29), ISBLANK(H29)), "", IFERROR(NETWORKDAYS(F29, H29), "")) -> 17
A30: 45734 | B30: 23412247000110 | C30: =VLOOKUP(B30,Fornecedores!A:B,2,0) -> AMAZON AWS SERVICOS BRASIL LTDA | D30: INGRID | E30: 04093699 | F30: 45718 | G30: 510096.46 | H30: =VLOOKUP(E30&B30,'Conf Oracle'!A:F,6,0) -> 45747.502 | J30: =IF(OR(ISBLANK(F30), ISBLANK(H30)), "", IFERROR(NETWORKDAYS(F30, H30), "")) -> 21
A31: 45734 | B31: 23412247000110 | C31: =VLOOKUP(B31,Fornecedores!A:B,2,0) -> AMAZON AWS SERVICOS BRASIL LTDA | D31: INGRID | E31: 04095146 | F31: 45718 | G31: 71814.74 | H31: =VLOOKUP(E31&B31,'Conf Oracle'!A:F,6,0) -> 45747.604 | J31: =IF(OR(ISBLANK(F31), ISBLANK(H31)), "", IFERROR(NETWORKDAYS(F31, H31), "")) -> 21
A32: 45734 | B32: 23412247000110 | C32: =VLOOKUP(B32,Fornecedores!A:B,2,0) -> AMAZON AWS SERVICOS BRASIL LTDA | D32: INGRID | E32: 04095151 | F32: 45718 | G32: 50287.76 | H32: =VLOOKUP(E32&B32,'Conf Oracle'!A:F,6,0) -> 45747.622 | J32: =IF(OR(ISBLANK(F32), ISBLANK(H32)), "", IFERROR(NETWORKDAYS(F32, H32), "")) -> 21
A33: 45734 | B33: 58652678000139 | C33: =VLOOKUP(B33,Fornecedores!A:B,2,0) -> COLUMBIA STORAGE INTEGR DE SITEMAS LTDA | D33: INGRID | E33: 00011049 | F33: 45722 | G33: 17116.41 | H33: =VLOOKUP(E33&B33,'Conf Oracle'!A:F,6,0) -> 45736.396 | J33: =IF(OR(ISBLANK(F33), ISBLANK(H33)), "", IFERROR(NETWORKDAYS(F33, H33), "")) -> 11
A34: 45734 | B34: 07850212000107 | C34: =VLOOKUP(B34,Fornecedores!A:B,2,0) -> REAL SEGURANCA INTEGRADA EIRELI | D34: INGRID | E34: 00001089 | F34: 45722 | G34: 217.9 | H34: =VLOOKUP(E34&B34,'Conf Oracle'!A:F,6,0) -> 45747.459 | J34: =IF(OR(ISBLANK(F34), ISBLANK(H34)), "", IFERROR(NETWORKDAYS(F34, H34), "")) -> 18
A35: 45734 | B35: 02558157000162 | C35: =VLOOKUP(B35,Fornecedores!A:B,2,0) -> TELEFONICA BRASIL SA | D35: INGRID | E35: 19504125 | F35: 45710 | G35: 29.19 | H35: =VLOOKUP(E35&B35,'Conf Oracle'!A:F,6,0) -> #N/A | I35: Em contestação | J35: =IF(OR(ISBLANK(F35), ISBLANK(H35)), "", IFERROR(NETWORKDAYS(F35, H35), ""))
A36: 45734 | B36: 02558157000162 | C36: =VLOOKUP(B36,Fornecedores!A:B,2,0) -> TELEFONICA BRASIL SA | D36: INGRID | E36: 13969264 | F36: 45710 | G36: 425.93 | H36: =VLOOKUP(E36&B36,'Conf Oracle'!A:F,6,0) -> #N/A | I36: Em contestação | J36: =IF(OR(ISBLANK(F36), ISBLANK(H36)), "", IFERROR(NETWORKDAYS(F36, H36), ""))
A37: 45734 | B37: 01768873000101 | C37: =VLOOKUP(B37,Fornecedores!A:B,2,0) -> AMCOM SISTEMAS DE INFORMACAO SA | D37: INGRID | E37: 00019090 | F37: 45723 | G37: 47600 | H37: =VLOOKUP(E37&B37,'Conf Oracle'!A:F,6,0) -> 45727.404 | J37: =IF(OR(ISBLANK(F37), ISBLANK(H37)), "", IFERROR(NETWORKDAYS(F37, H37), "")) -> 3
A38: 45734 | B38: 01768873000101 | C38: =VLOOKUP(B38,Fornecedores!A:B,2,0) -> AMCOM SISTEMAS DE INFORMACAO SA | D38: INGRID | E38: 00019091 | F38: 45723 | G38: 200600 | H38: =VLOOKUP(E38&B38,'Conf Oracle'!A:F,6,0) -> 45727.416 | J38: =IF(OR(ISBLANK(F38), ISBLANK(H38)), "", IFERROR(NETWORKDAYS(F38, H38), "")) -> 3
A39: 45734 | B39: 01768873000101 | C39: =VLOOKUP(B39,Fornecedores!A:B,2,0) -> AMCOM SISTEMAS DE INFORMACAO SA | D39: INGRID | E39: 00019092 | F39: 45723 | G39: 167790 | H39: =VLOOKUP(E39&B39,'Conf Oracle'!A:F,6,0) -> 45727.438 | J39: =IF(OR(ISBLANK(F39), ISBLANK(H39)), "", IFERROR(NETWORKDAYS(F39, H39), "")) -> 3
A40: 45734 | B40: 01768873000101 | C40: =VLOOKUP(B40,Fornecedores!A:B,2,0) -> AMCOM SISTEMAS DE INFORMACAO SA | D40: INGRID | E40: 00019093 | F40: 45723 | G40: 125120 | H40: =VLOOKUP(E40&B40,'Conf Oracle'!A:F,6,0) -> 45741.68 | J40: =IF(OR(ISBLANK(F40), ISBLANK(H40)), "", IFERROR(NETWORKDAYS(F40, H40), "")) -> 13
A41: 45734 | B41: 01768873000101 | C41: =VLOOKUP(B41,Fornecedores!A:B,2,0) -> AMCOM SISTEMAS DE INFORMACAO SA | D41: INGRID | E41: 00019094 | F41: 45723 | G41: 86700 | H41: =VLOOKUP(E41&B41,'Conf Oracle'!A:F,6,0) -> 45727.617 | J41: =IF(OR(ISBLANK(F41), ISBLANK(H41)), "", IFERROR(NETWORKDAYS(F41, H41), "")) -> 3
A42: 45734 | B42: 01768873000101 | C42: =VLOOKUP(B42,Fornecedores!A:B,2,0) -> AMCOM SISTEMAS DE INFORMACAO SA | D42: INGRID | E42: 00019095 | F42: 45723 | G42: 205360 | H42: =VLOOKUP(E42&B42,'Conf Oracle'!A:F,6,0) -> 45727.465 | J42: =IF(OR(ISBLANK(F42), ISBLANK(H42)), "", IFERROR(NETWORKDAYS(F42, H42), "")) -> 3
...

Sheet Controle de NF - Fevereiro
A2: Mês | B2: CNPJ | C2: Fornecedor | D2: Gestor Adm | E2: NF | F2: Emissão da NF | G2: Valor da NF | H2: Conferência | I2: Observação | J2: SLA
A3: 45705 | B3: 16554325000156 | C3: =VLOOKUP(B3,Fornecedores!A:B,2,0) -> AMBIENTE VERDE RESIDUOS LTDA | D3: EVANDREA | E3: 00000735 | F3: 45691 | G3: 2690 | H3: =VLOOKUP(E3&B3,'Conf Oracle'!A:F,6,0) -> 45708.666 | I3: não lançada | J3: =IF(OR(ISBLANK(F3), ISBLANK(H3)), "", IFERROR(NETWORKDAYS(F3, H3), "")) -> 14
A4: 45705 | B4: 16554325000156 | C4: =VLOOKUP(B4,Fornecedores!A:B,2,0) -> AMBIENTE VERDE RESIDUOS LTDA | D4: EVANDREA | E4: 00000741 | F4: 45692 | G4: 2490 | H4: =VLOOKUP(E4&B4,'Conf Oracle'!A:F,6,0) -> #N/A | I4: não lançada verificar se há duplicidade | J4: =IF(OR(ISBLANK(F4), ISBLANK(H4)), "", IFERROR(NETWORKDAYS(F4, H4), ""))
A5: 45705 | B5: 16554325000156 | C5: =VLOOKUP(B5,Fornecedores!A:B,2,0) -> AMBIENTE VERDE RESIDUOS LTDA | D5: EVANDREA | E5: 00000742 | F5: 45692 | G5: 2690 | H5: =VLOOKUP(E5&B5,'Conf Oracle'!A:F,6,0) -> 45708.657 | I5: não lançada | J5: =IF(OR(ISBLANK(F5), ISBLANK(H5)), "", IFERROR(NETWORKDAYS(F5, H5), "")) -> 13
A6: 45705 | B6: 08270682000164 | C6: =VLOOKUP(B6,Fornecedores!A:B,2,0) -> CONFIDERE IMOBILIARIA LTDA | D6: EVANDREA | E6: 00202502 | F6: 45689 | G6: 2737093.3 | H6: =VLOOKUP(E6&B6,'Conf Oracle'!A:F,6,0) -> 45701.496 | J6: =IF(OR(ISBLANK(F6), ISBLANK(H6)), "", IFERROR(NETWORKDAYS(F6, H6), "")) -> 9
A7: 45705 | B7: 16554325000156 | C7: =VLOOKUP(B7,Fornecedores!A:B,2,0) -> AMBIENTE VERDE RESIDUOS LTDA | D7: EVANDREA | E7: 00000750 | F7: 45692 | G7: 2490 | H7: =VLOOKUP(E7&B7,'Conf Oracle'!A:F,6,0) -> 45708.42 | I7: não lançada verificar se há duplicidade | J7: =IF(OR(ISBLANK(F7), ISBLANK(H7)), "", IFERROR(NETWORKDAYS(F7, H7), "")) -> 13
A8: 45705 | B8: 29650979000125 | C8: =VLOOKUP(B8,Fornecedores!A:B,2,0) -> CAPACITARE RECURSOS HUMANOS EIRELI | D8: EVANDREA | E8: 00002158 | F8: 45692 | G8: 16560 | H8: =VLOOKUP(E8&B8,'Conf Oracle'!A:F,6,0) -> 45708.682 | I8: não lançada | J8: =IF(OR(ISBLANK(F8), ISBLANK(H8)), "", IFERROR(NETWORKDAYS(F8, H8), "")) -> 13
A9: 45705 | B9: 00028986001694 | C9: =VLOOKUP(B9,Fornecedores!A:B,2,0) -> ELEVADORES ATLAS SCHINDLER SA | D9: EVANDREA | E9: 00463366 | F9: 45693 | G9: 1960.94 | H9: =VLOOKUP(E9&B9,'Conf Oracle'!A:F,6,0) -> 45705.373 | J9: =IF(OR(ISBLANK(F9), ISBLANK(H9)), "", IFERROR(NETWORKDAYS(F9, H9), "")) -> 9
A10: 45705 | B10: 16554325000156 | C10: =VLOOKUP(B10,Fornecedores!A:B,2,0) -> AMBIENTE VERDE RESIDUOS LTDA | D10: EVANDREA | E10: 00000760 | F10: 45693 | G10: 8839.27 | H10: =VLOOKUP(E10&B10,'Conf Oracle'!A:F,6,0) -> 45713.33 | I10: não lançada | J10: =IF(OR(ISBLANK(F10), ISBLANK(H10)), "", IFERROR(NETWORKDAYS(F10, H10), "")) -> 15
A11: 45705 | B11: 90347840005691 | C11: =VLOOKUP(B11,Fornecedores!A:B,2,0) -> TK ELEVADORES BRASIL LTDA. | D11: EVANDREA | E11: 00111690 | F11: 45691 | G11: 13781.17 | H11: =VLOOKUP(E11&B11,'Conf Oracle'!A:F,6,0) -> 45712.443 | I11: não lançada | J11: =IF(OR(ISBLANK(F11), ISBLANK(H11)), "", IFERROR(NETWORKDAYS(F11, H11), "")) -> 16
A12: 45705 | B12: 00973749000115 | C12: =VLOOKUP(B12,Fornecedores!A:B,2,0) -> TOP SERVICE SERVICOS E SISTEMAS S/A | D12: EVANDREA | E12: 00209441 | F12: 45700 | G12: 128116.16 | H12: =VLOOKUP(E12&B12,'Conf Oracle'!A:F,6,0) -> 45715.577 | I12: não lançada | J12: =IF(OR(ISBLANK(F12), ISBLANK(H12)), "", IFERROR(NETWORKDAYS(F12, H12), "")) -> 12
A13: 45705 | B13: 05208211000138 | C13: =VLOOKUP(B13,Fornecedores!A:B,2,0) -> IN-HAUS INDUSTRIAL E SERVICOS DE LOGISTICA LTDA | D13: EVANDREA | E13: 00116491 | F13: 45700 | G13: 102014.63 | H13: =VLOOKUP(E13&B13,'Conf Oracle'!A:F,6,0) -> 45715.442 | I13: não lançada | J13: =IF(OR(ISBLANK(F13), ISBLANK(H13)), "", IFERROR(NETWORKDAYS(F13, H13), "")) -> 12
A14: 45705 | B14: 00082024000137 | C14: =VLOOKUP(B14,Fornecedores!A:B,2,0) -> COMPANHIA DE SANEAMENTO AMBIENTAL DO DISTRITO FEDERAL | D14: EVANDREA | E14: 00022025 | F14: 45701 | G14: 20344.29 | H14: =VLOOKUP(E14&B14,'Conf Oracle'!A:F,6,0) -> #N/A | I14: não lançada | J14: =IF(OR(ISBLANK(F14), ISBLANK(H14)), "", IFERROR(NETWORKDAYS(F14, H14), ""))
A15: 45705 | B15: 23412247000110 | C15: =VLOOKUP(B15,Fornecedores!A:B,2,0) -> AMAZON AWS SERVICOS BRASIL LTDA | D15: INGRID | E15: 03992954 | F15: 45690 | G15: 584634.01 | H15: =VLOOKUP(E15&B15,'Conf Oracle'!A:F,6,0) -> 45722.639 | J15: =IF(OR(ISBLANK(F15), ISBLANK(H15)), "", IFERROR(NETWORKDAYS(F15, H15), "")) -> 24
A16: 45705 | B16: 23412247000110 | C16: =VLOOKUP(B16,Fornecedores!A:B,2,0) -> AMAZON AWS SERVICOS BRASIL LTDA | D16: INGRID | E16: 28672561 | F16: 45689 | G16: 584631.74 | H16: =VLOOKUP(E16&B16,'Conf Oracle'!A:F,6,0) -> #N/A | J16: =IF(OR(ISBLANK(F16), ISBLANK(H16)), "", IFERROR(NETWORKDAYS(F16, H16), ""))
A17: 45705 | B17: 23412247000110 | C17: =VLOOKUP(B17,Fornecedores!A:B,2,0) -> AMAZON AWS SERVICOS BRASIL LTDA | D17: INGRID | E17: 03993947 | F17: 45690 | G17: 71814.74 | H17: =VLOOKUP(E17&B17,'Conf Oracle'!A:F,6,0) -> 45722.671 | J17: =IF(OR(ISBLANK(F17), ISBLANK(H17)), "", IFERROR(NETWORKDAYS(F17, H17), "")) -> 24
A18: 45705 | B18: 23412247000110 | C18: =VLOOKUP(B18,Fornecedores!A:B,2,0) -> AMAZON AWS SERVICOS BRASIL LTDA | D18: INGRID | E18: 03993950 | F18: 45690 | G18: 42206.14 | H18: =VLOOKUP(E18&B18,'Conf Oracle'!A:F,6,0) -> 45722.66 | J18: =IF(OR(ISBLANK(F18), ISBLANK(H18)), "", IFERROR(NETWORKDAYS(F18, H18), "")) -> 24
A19: 45705 | B19: 23412247000110 | C19: =VLOOKUP(B19,Fornecedores!A:B,2,0) -> AMAZON AWS SERVICOS BRASIL LTDA | D19: INGRID | E19: 28766029 | F19: 45689 | G19: 114021.02 | H19: =VLOOKUP(E19&B19,'Conf Oracle'!A:F,6,0) -> #N/A | J19: =IF(OR(ISBLANK(F19), ISBLANK(H19)), "", IFERROR(NETWORKDAYS(F19, H19), ""))
A20: 45705 | B20: 07850212000107 | C20: =VLOOKUP(B20,Fornecedores!A:B,2,0) -> REAL SEGURANCA INTEGRADA EIRELI | D20: INGRID | E20: 00001052 | F20: 45692 | G20: 222.35 | H20: =VLOOKUP(E20&B20,'Conf Oracle'!A:F,6,0) -> #N/A | J20: =IF(OR(ISBLANK(F20), ISBLANK(H20)), "", IFERROR(NETWORKDAYS(F20, H20), ""))
A21: 45705 | B21: 96534094000158 | C21: =VLOOKUP(B21,Fornecedores!A:B,2,0) -> ACCENTURE DO BRASIL LTDA | D21: INGRID | E21: 00101006 | F21: 45698 | G21: 183243.6 | H21: =VLOOKUP(E21&B21,'Conf Oracle'!A:F,6,0) -> 45722.653 | J21: =IF(OR(ISBLANK(F21), ISBLANK(H21)), "", IFERROR(NETWORKDAYS(F21, H21), "")) -> 19
A22: 45705 | B22: 96534094000158 | C22: =VLOOKUP(B22,Fornecedores!A:B,2,0) -> ACCENTURE DO BRASIL LTDA | D22: INGRID | E22: 00101007 | F22: 45698 | G22: 43999.2 | H22: =VLOOKUP(E22&B22,'Conf Oracle'!A:F,6,0) -> 45722.621 | J22: =IF(OR(ISBLANK(F22), ISBLANK(H22)), "", IFERROR(NETWORKDAYS(F22, H22), "")) -> 19
A23: 45705 | B23: 02558157013574 | C23: =VLOOKUP(B23,Fornecedores!A:B,2,0) -> TELEFONICA BRASIL SA | D23: INGRID | E23: 00295537 | F23: 45696 | G23: 1110.62 | H23: =VLOOKUP(E23&B23,'Conf Oracle'!A:F,6,0) -> #N/A | J23: =IF(OR(ISBLANK(F23), ISBLANK(H23)), "", IFERROR(NETWORKDAYS(F23, H23), ""))
A24: 45705 | B24: 02558157013574 | C24: =VLOOKUP(B24,Fornecedores!A:B,2,0) -> TELEFONICA BRASIL SA | D24: INGRID | E24: 00297385 | F24: 45696 | G24: 360 | H24: =VLOOKUP(E24&B24,'Conf Oracle'!A:F,6,0) -> #N/A | J24: =IF(OR(ISBLANK(F24), ISBLANK(H24)), "", IFERROR(NETWORKDAYS(F24, H24), ""))
A25: 45705 | B25: 02558157013574 | C25: =VLOOKUP(B25,Fornecedores!A:B,2,0) -> TELEFONICA BRASIL SA | D25: INGRID | E25: 00292887 | F25: 45696 | G25: 882.79 | H25: =VLOOKUP(E25&B25,'Conf Oracle'!A:F,6,0) -> #N/A | J25: =IF(OR(ISBLANK(F25), ISBLANK(H25)), "", IFERROR(NETWORKDAYS(F25, H25), ""))
A26: 45705 | B26: 02558157013574 | C26: =VLOOKUP(B26,Fornecedores!A:B,2,0) -> TELEFONICA BRASIL SA | D26: INGRID | E26: 00293088 | F26: 45696 | G26: 1080 | H26: =VLOOKUP(E26&B26,'Conf Oracle'!A:F,6,0) -> #N/A | J26: =IF(OR(ISBLANK(F26), ISBLANK(H26)), "", IFERROR(NETWORKDAYS(F26, H26), ""))
... A35: 45705 | B35: 00593850000221 | C35: =VLOOKUP(B35,Fornecedores!A:B,2,0) -> RERUM ENGENHARIA DE SISTEMAS LTDA | D35: INGRID | E35: 00000645 | F35: 45699 | G35: 41287.84 | H35: =VLOOKUP(E35&B35,'Conf Oracle'!A:F,6,0) -> #N/A | J35: =IF(OR(ISBLANK(F35), ISBLANK(H35)), "", IFERROR(NETWORKDAYS(F35, H35), ""))
A36: 45705 | B36: 07850212000107 | C36: =VLOOKUP(B36,Fornecedores!A:B,2,0) -> REAL SEGURANCA INTEGRADA EIRELI | D36: INGRID | E36: 00001080 | F36: 45700 | G36: 217.9 | H36: =VLOOKUP(E36&B36,'Conf Oracle'!A:F,6,0) -> 45700.671 | I36: NF COM MESMO NÚMERO DE FORNECEDORES DIFERENTES | J36: =IF(OR(ISBLANK(F36), ISBLANK(H36)), "", IFERROR(NETWORKDAYS(F36, H36), "")) -> 1
A37: 45705 | B37: 02408485000182 | C37: =VLOOKUP(B37,Fornecedores!A:B,2,0) -> MULTIVIS BRASIL LTDA | D37: INGRID | E37: 00002480 | F37: 45700 | G37: 76829.38 | H37: =VLOOKUP(E37&B37,'Conf Oracle'!A:F,6,0) -> 45722.586 | J37: =IF(OR(ISBLANK(F37), ISBLANK(H37)), "", IFERROR(NETWORKDAYS(F37, H37), "")) -> 17
A38: 45705 | B38: 26409092000151 | C38: =VLOOKUP(B38,Fornecedores!A:B,2,0) -> SSAMRO SOLUCOES PARA MANUTENCAO INDUSTR | D38: ISABELA | E38: 00024003 | F38: 45691 | G38: 648.76 | H38: =VLOOKUP(E38&B38,'Conf Oracle'!A:F,6,0) -> 45699.377 | J38: =IF(OR(ISBLANK(F38), ISBLANK(H38)), "", IFERROR(NETWORKDAYS(F38, H38), "")) -> 7
A39: 45705 | B39: 26409092000151 | C39: =VLOOKUP(B39,Fornecedores!A:B,2,0) -> SSAMRO SOLUCOES PARA MANUTENCAO INDUSTR | D39: ISABELA | E39: 00024008 | F39: 45691 | G39: 648.76 | H39: =VLOOKUP(E39&B39,'Conf Oracle'!A:F,6,0) -> 45699.375 | J39: =IF(OR(ISBLANK(F39), ISBLANK(H39)), "", IFERROR(NETWORKDAYS(F39, H39), "")) -> 7
A40: 45705 | B40: 26409092000151 | C40: =VLOOKUP(B40,Fornecedores!A:B,2,0) -> SSAMRO SOLUCOES PARA MANUTENCAO INDUSTR | D40: ISABELA | E40: 00024016 | F40: 45691 | G40: 648.76 | H40: =VLOOKUP(E40&B40,'Conf Oracle'!A:F,6,0) -> 45699.374 | J40: =IF(OR(ISBLANK(F40), ISBLANK(H40)), "", IFERROR(NETWORKDAYS(F40, H40), "")) -> 7
A41: 45705 | B41: 26409092000151 | C41: =VLOOKUP(B41,Fornecedores!A:B,2,0) -> SSAMRO SOLUCOES PARA MANUTENCAO INDUSTR | D41: ISABELA | E41: 00024024 | F41: 45691 | G41: 648.76 | H41: =VLOOKUP(E41&B41,'Conf Oracle'!A:F,6,0) -> 45699.372 | J41: =IF(OR(ISBLANK(F41), ISBLANK(H41)), "", IFERROR(NETWORKDAYS(F41, H41), "")) -> 7
A42: 45705 | B42: 07751071000175 | C42: =VLOOKUP(B42,Fornecedores!A:B,2,0) -> TELEGESTAO SISTEMAS DE ATEND LTDA | D42: ISABELA | E42: 00000876 | F42: 45691 | G42: 700 | H42: =VLOOKUP(E42&B42,'Conf Oracle'!A:F,6,0) -> 45698.483 | J42: =IF(OR(ISBLANK(F42), ISBLANK(H42)), "", IFERROR(NETWORKDAYS(F42, H42), "")) -> 6
A43: 45705 | B43: 69034668000156 | C43: =VLOOKUP(B43,Fornecedores!A:B,2,0) -> PLUXEE BENEFICIOS BRASIL SA | D43: ISABELA | E43: 04356679 | F43: 45692 | G43: 1981.41 | H43: =VLOOKUP(E43&B43,'Conf Oracle'!A:F,6,0) -> 45693.652 | J43: =IF(OR(ISBLANK(F43), ISBLANK(H43)), "", IFERROR(NETWORKDAYS(F43, H43), "")) -> 2
A44: 45705 | B44: 69034668000156 | C44: =VLOOKUP(B44,Fornecedores!A:B,2,0) -> PLUXEE BENEFICIOS BRASIL SA | D44: ISABELA | E44: 04356677 | F44: 45692 | G44: 4946.59 | H44: =VLOOKUP(E44&B44,'Conf Oracle'!A:F,6,0) -> 45693.698 | J44: =IF(OR(ISBLANK(F44), ISBLANK(H44)), "", IFERROR(NETWORKDAYS(F44, H44), "")) -> 2
A45: 45705 | B45: 15491115000101 | C45: =VLOOKUP(B45,Fornecedores!A:B,2,0) -> CS INTEGRA SOLUCOES EM TECNOLOG LTDA ME | D45: ISABELA | E45: 00006163 | F45: 45692 | G45: 3093 | H45: =VLOOKUP(E45&B45,'Conf Oracle'!A:F,6,0) -> 45698.402 | J45: =IF(OR(ISBLANK(F45), ISBLANK(H45)), "", IFERROR(NETWORKDAYS(F45, H45), "")) -> 5
A46: 45705 | B46: 72157654000215 | C46: =VLOOKUP(B46,Fornecedores!A:B,2,0) -> VELA SOFTWARE E SERVICOS LTDA | D46: ISABELA | E46: 00003085 | F46: 45693 | G46: 677.6 | H46: =VLOOKUP(E46&B46,'Conf Oracle'!A:F,6,0) -> #N/A | J46: =IF(OR(ISBLANK(F46), ISBLANK(H46)), "", IFERROR(NETWORKDAYS(F46, H46), ""))
A47: 45705 | B47: 72157654000215 | C47: =VLOOKUP(B47,Fornecedores!A:B,2,0) -> VELA SOFTWARE E SERVICOS LTDA | D47: ISABELA | E47: 00003086 | F47: 45693 | G47: 677.6 | H47: =VLOOKUP(E47&B47,'Conf Oracle'!A:F,6,0) -> #N/A | J47: =IF(OR(ISBLANK(F47), ISBLANK(H47)), "", IFERROR(NETWORKDAYS(F47, H47), ""))
A48: 45705 | B48: 72157654000215 | C48: =VLOOKUP(B48,Fornecedores!A:B,2,0) -> VELA SOFTWARE E SERVICOS LTDA | D48: ISABELA | E48: 00003089 | F48: 45693 | G48: 677.6 | H48: =VLOOKUP(E48&B48,'Conf Oracle'!A:F,6,0) -> #N/A | J48: =IF(OR(ISBLANK(F48), ISBLANK(H48)), "", IFERROR(NETWORKDAYS(F48, H48), ""))
... A78: 45705 | B78: 09305983000149 | C78: =VLOOKUP(B78,Fornecedores!A:B,2,0) -> PSR SOLUCOES CONSULTORIA EM ENERGIA LTDA | D78: PEDRO | E78: 00013307 | F78: 45693 | G78: 120000 | H78: =VLOOKUP(E78&B78,'Conf Oracle'!A:F,6,0) -> 45698.382 | J78: =IF(OR(ISBLANK(F78), ISBLANK(H78)), "", IFERROR(NETWORKDAYS(F78, H78), "")) -> 4
...

Sheet Controle de NF - Junho
A2: Mês | B2: CNPJ | C2: Fornecedor | D2: Gestor Adm | E2: NF | F2: Emissão da NF | G2: Valor da NF | H2: Conferência | I2: Observação | J2: SLA
A3: 45810 | B3: 03368287000103 | C3: =VLOOKUP(B3,Fornecedores!A:B,2,0) -> CTY INFORMATICA LTDA ME | D3: Ingrid | E3: 00012228 | F3: 45809 | G3: 14366.6 | H3: =VLOOKUP(E3&B3,'Conf Oracle'!A:F,6,0) -> 45820.576 | J3: =IF(OR(ISBLANK(F3), ISBLANK(H3)), "", IFERROR(NETWORKDAYS(F3, H3), "")) -> 9
A4: 45810 | B4: 58652678000139 | C4: =VLOOKUP(B4,Fornecedores!A:B,2,0) -> COLUMBIA STORAGE INTEGR DE SITEMAS LTDA | D4: Ingrid | E4: 00011156 | F4: 45810 | G4: 17116.41 | H4: =VLOOKUP(E4&B4,'Conf Oracle'!A:F,6,0) -> 45819.69 | J4: =IF(OR(ISBLANK(F4), ISBLANK(H4)), "", IFERROR(NETWORKDAYS(F4, H4), "")) -> 8
A5: 45810 | B5: 23412247000110 | C5: =VLOOKUP(B5,Fornecedores!A:B,2,0) -> AMAZON AWS SERVICOS BRASIL LTDA | D5: Ingrid | E5: 04406862 | F5: 45809 | G5: 63034.39 | H5: =VLOOKUP(E5&B5,'Conf Oracle'!A:F,6,0) -> 45833.708 | I5: OC_0009834 | J5: =IF(OR(ISBLANK(F5), ISBLANK(H5)), "", IFERROR(NETWORKDAYS(F5, H5), "")) -> 18
A6: 45810 | B6: 23412247000110 | C6: =VLOOKUP(B6,Fornecedores!A:B,2,0) -> AMAZON AWS SERVICOS BRASIL LTDA | D6: Ingrid | E6: 04406853 | F6: 45809 | G6: 71814.74 | H6: =VLOOKUP(E6&B6,'Conf Oracle'!A:F,6,0) -> #N/A | I6: OC_0009835 | J6: =IF(OR(ISBLANK(F6), ISBLANK(H6)), "", IFERROR(NETWORKDAYS(F6, H6), ""))
A7: 45810 | B7: 23412247000110 | C7: =VLOOKUP(B7,Fornecedores!A:B,2,0) -> AMAZON AWS SERVICOS BRASIL LTDA | D7: Ingrid | E7: 04403745 | F7: 45809 | G7: 617836.05 | H7: =VLOOKUP(E7&B7,'Conf Oracle'!A:F,6,0) -> 45833.713 | J7: =IF(OR(ISBLANK(F7), ISBLANK(H7)), "", IFERROR(NETWORKDAYS(F7, H7), "")) -> 18
A8: 45810 | B8: 07751071000175 | C8: =VLOOKUP(B8,Fornecedores!A:B,2,0) -> TELEGESTAO SISTEMAS DE ATEND LTDA | D8: Isabela | E8: 00001155 | F8: 45809 | G8: 700 | H8: =VLOOKUP(E8&B8,'Conf Oracle'!A:F,6,0) -> 45814.456 | J8: =IF(OR(ISBLANK(F8), ISBLANK(H8)), "", IFERROR(NETWORKDAYS(F8, H8), "")) -> 5
A9: 45810 | B9: 72157654000215 | C9: =VLOOKUP(B9,Fornecedores!A:B,2,0) -> VELA SOFTWARE E SERVICOS LTDA | D9: Isabela | E9: 20259372R | F9: 45810 | G9: 677.6 | H9: =VLOOKUP(E9&B9,'Conf Oracle'!A:F,6,0) -> 45819.645 | I9: Lançada | J9: =IF(OR(ISBLANK(F9), ISBLANK(H9)), "", IFERROR(NETWORKDAYS(F9, H9), "")) -> 8
A10: 45810 | B10: 72157654000215 | C10: =VLOOKUP(B10,Fornecedores!A:B,2,0) -> VELA SOFTWARE E SERVICOS LTDA | D10: Isabela | E10: 2029378R | F10: 45810 | G10: 677.6 | H10: =VLOOKUP(E10&B10,'Conf Oracle'!A:F,6,0) -> 45821.419 | I10: Lançada | J10: =IF(OR(ISBLANK(F10), ISBLANK(H10)), "", IFERROR(NETWORKDAYS(F10, H10), "")) -> 10
A11: 45810 | B11: 26409092000151 | C11: =VLOOKUP(B11,Fornecedores!A:B,2,0) -> SSAMRO SOLUCOES PARA MANUTENCAO INDUSTR | D11: Isabela | E11: 00025115 | F11: 45810 | G11: 648.76 | H11: =VLOOKUP(E11&B11,'Conf Oracle'!A:F,6,0) -> 45814.444 | J11: =IF(OR(ISBLANK(F11), ISBLANK(H11)), "", IFERROR(NETWORKDAYS(F11, H11), "")) -> 5
A12: 45810 | B12: 26409092000151 | C12: =VLOOKUP(B12,Fornecedores!A:B,2,0) -> SSAMRO SOLUCOES PARA MANUTENCAO INDUSTR | D12: Isabela | E12: 00025125 | F12: 45810 | G12: 648.76 | H12: =VLOOKUP(E12&B12,'Conf Oracle'!A:F,6,0) -> 45814.438 | J12: =IF(OR(ISBLANK(F12), ISBLANK(H12)), "", IFERROR(NETWORKDAYS(F12, H12), "")) -> 5
A13: 45810 | B13: 26409092000151 | C13: =VLOOKUP(B13,Fornecedores!A:B,2,0) -> SSAMRO SOLUCOES PARA MANUTENCAO INDUSTR | D13: Isabela | E13: 00025131 | F13: 45810 | G13: 648.76 | H13: =VLOOKUP(E13&B13,'Conf Oracle'!A:F,6,0) -> 45814.435 | J13: =IF(OR(ISBLANK(F13), ISBLANK(H13)), "", IFERROR(NETWORKDAYS(F13, H13), "")) -> 5
A14: 45810 | B14: 26409092000151 | C14: =VLOOKUP(B14,Fornecedores!A:B,2,0) -> SSAMRO SOLUCOES PARA MANUTENCAO INDUSTR | D14: Isabela | E14: 00025133 | F14: 45810 | G14: 648.76 | H14: =VLOOKUP(E14&B14,'Conf Oracle'!A:F,6,0) -> 45814.437 | J14: =IF(OR(ISBLANK(F14), ISBLANK(H14)), "", IFERROR(NETWORKDAYS(F14, H14), "")) -> 5
A15: 45813 | B15: 00191027000109 | C15: =VLOOKUP(B15,Fornecedores!A:B,2,0) -> FACILIT TECNOLOGIA LTDA EPP | D15: Sunara | E15: 00003719 | F15: 45810 | G15: 13496 | H15: =VLOOKUP(E15&B15,'Conf Oracle'!A:F,6,0) -> 45820.598 | J15: =IF(OR(ISBLANK(F15), ISBLANK(H15)), "", IFERROR(NETWORKDAYS(F15, H15), "")) -> 9
A16: 45810 | B16: 81785545000152 | C16: =VLOOKUP(B16,Fornecedores!A:B,2,0) -> DEL GRANDE INFO E TELEC IND E COM LTDA | D16: Pedro | E16: 00004150 | F16: 45810 | G16: 5077 | H16: =VLOOKUP(E16&B16,'Conf Oracle'!A:F,6,0) -> 45826.649 | J16: =IF(OR(ISBLANK(F16), ISBLANK(H16)), "", IFERROR(NETWORKDAYS(F16, H16), "")) -> 13
A17: 45810 | B17: 81785545000152 | C17: =VLOOKUP(B17,Fornecedores!A:B,2,0) -> DEL GRANDE INFO E TELEC IND E COM LTDA | D17: Pedro | E17: 00004151 | F17: 45810 | G17: 1618.7 | H17: =VLOOKUP(E17&B17,'Conf Oracle'!A:F,6,0) -> 45826.655 | J17: =IF(OR(ISBLANK(F17), ISBLANK(H17)), "", IFERROR(NETWORKDAYS(F17, H17), "")) -> 13
A18: 45810 | B18: 81785545000152 | C18: =VLOOKUP(B18,Fornecedores!A:B,2,0) -> DEL GRANDE INFO E TELEC IND E COM LTDA | D18: Pedro | E18: 00004153 | F18: 45810 | G18: 2825.73 | H18: =VLOOKUP(E18&B18,'Conf Oracle'!A:F,6,0) -> 45826.651 | J18: =IF(OR(ISBLANK(F18), ISBLANK(H18)), "", IFERROR(NETWORKDAYS(F18, H18), "")) -> 13
A19: 45810 | B19: 81785545000152 | C19: =VLOOKUP(B19,Fornecedores!A:B,2,0) -> DEL GRANDE INFO E TELEC IND E COM LTDA | D19: Pedro | E19: 00004152 | F19: 45810 | G19: 3151.24 | H19: =VLOOKUP(E19&B19,'Conf Oracle'!A:F,6,0) -> 45826.653 | J19: =IF(OR(ISBLANK(F19), ISBLANK(H19)), "", IFERROR(NETWORKDAYS(F19, H19), "")) -> 13
A20: 45813 | B20: 16554325000156 | C20: =VLOOKUP(B20,Fornecedores!A:B,2,0) -> AMBIENTE VERDE RESIDUOS LTDA | D20: Evandrea | E20: 00001035 | F20: 45810 | G20: 2690 | H20: =VLOOKUP(E20&B20,'Conf Oracle'!A:F,6,0) -> 45817.44 | J20: =IF(OR(ISBLANK(F20), ISBLANK(H20)), "", IFERROR(NETWORKDAYS(F20, H20), "")) -> 6
A21: 45813 | B21: 16554325000156 | C21: =VLOOKUP(B21,Fornecedores!A:B,2,0) -> AMBIENTE VERDE RESIDUOS LTDA | D21: Evandrea | E21: 00001034 | F21: 45810 | G21: 2690 | H21: =VLOOKUP(E21&B21,'Conf Oracle'!A:F,6,0) -> 45817.425 | J21: =IF(OR(ISBLANK(F21), ISBLANK(H21)), "", IFERROR(NETWORKDAYS(F21, H21), "")) -> 6
A22: 45813 | B22: 57623555000107 | C22: =VLOOKUP(B22,Fornecedores!A:B,2,0) -> MAGICCOMP ENG E SERV DE INFORMATICA LTDA | D22: Jessy | E22: 00055719 | F22: 45810 | G22: 27750 | H22: =VLOOKUP(E22&B22,'Conf Oracle'!A:F,6,0) -> 45824.604 | I22: Ok | J22: =IF(OR(ISBLANK(F22), ISBLANK(H22)), "", IFERROR(NETWORKDAYS(F22, H22), "")) -> 11
A23: 45813 | B23: 57623555000107 | C23: =VLOOKUP(B23,Fornecedores!A:B,2,0) -> MAGICCOMP ENG E SERV DE INFORMATICA LTDA | D23: Jessy | E23: 00055718 | F23: 45810 | G23: 27750 | H23: =VLOOKUP(E23&B23,'Conf Oracle'!A:F,6,0) -> 45824.596 | I23: Ok | J23: =IF(OR(ISBLANK(F23), ISBLANK(H23)), "", IFERROR(NETWORKDAYS(F23, H23), "")) -> 11
A24: 45813 | B24: 57623555000107 | C24: =VLOOKUP(B24,Fornecedores!A:B,2,0) -> MAGICCOMP ENG E SERV DE INFORMATICA LTDA | D24: Jessy | E24: 00055717 | F24: 45810 | G24: 27750 | H24: =VLOOKUP(E24&B24,'Conf Oracle'!A:F,6,0) -> 45824.59 | I24: Ok | J24: =IF(OR(ISBLANK(F24), ISBLANK(H24)), "", IFERROR(NETWORKDAYS(F24, H24), "")) -> 11
A25: 45813 | B25: 57623555000107 | C25: =VLOOKUP(B25,Fornecedores!A:B,2,0) -> MAGICCOMP ENG E SERV DE INFORMATICA LTDA | D25: Jessy | E25: 00055720 | F25: 45810 | G25: 27750 | H25: =VLOOKUP(E25&B25,'Conf Oracle'!A:F,6,0) -> 45824.708 | I25: Ok | J25: =IF(OR(ISBLANK(F25), ISBLANK(H25)), "", IFERROR(NETWORKDAYS(F25, H25), "")) -> 11
A26: 45813 | B26: 08689542000125 | C26: =VLOOKUP(B26,Fornecedores!A:B,2,0) -> VOCS MULTIMIDIA PROD AUDIO VID LTDA EPP | D26: Jessy | E26: 00003404 | F26: 45810 | G26: 6286.2 | H26: =VLOOKUP(E26&B26,'Conf Oracle'!A:F,6,0) -> 45839.39 | I26: OC_0010021 | J26: =IF(OR(ISBLANK(F26), ISBLANK(H26)), "", IFERROR(NETWORKDAYS(F26, H26), "")) -> 22
A27: 45813 | B27: 08689542000125 | C27: =VLOOKUP(B27,Fornecedores!A:B,2,0) -> VOCS MULTIMIDIA PROD AUDIO VID LTDA EPP | D27: Jessy | E27: 00003403 | F27: 45810 | G27: 21000 | H27: =VLOOKUP(E27&B27,'Conf Oracle'!A:F,6,0) -> 45818.618 | I27: OC_0009644 | J27: =IF(OR(ISBLANK(F27), ISBLANK(H27)), "", IFERROR(NETWORKDAYS(F27, H27), "")) -> 7
A28: 45813 | B28: 01933257000169 | C28: =VLOOKUP(B28,Fornecedores!A:B,2,0) -> FUTURE TECHNOLOGIES INFORMATICA LTDA | D28: Jessy | E28: 00004511 | F28: 45810 | G28: 6450 | H28: =VLOOKUP(E28&B28,'Conf Oracle'!A:F,6,0) -> 45818.606 | I28: lançada - OC_0009643 | J28: =IF(OR(ISBLANK(F28), ISBLANK(H28)), "", IFERROR(NETWORKDAYS(F28, H28), "")) -> 7
A29: 45813 | B29: 15667402000111 | C29: =VLOOKUP(B29,Fornecedores!A:B,2,0) -> SIMPLE ENERGY ASSESSORIA E GESTAO DE ENERGIA LTDA. | D29: Evandrea | E29: 00021347 | F29: 45810 | G29: 733.38 | H29: =VLOOKUP(E29&B29,'Conf Oracle'!A:F,6,0) -> 45818.415 | J29: =IF(OR(ISBLANK(F29), ISBLANK(H29)), "", IFERROR(NETWORKDAYS(F29, H29), "")) -> 7
A30: 45813 | B30: 15667402000111 | C30: =VLOOKUP(B30,Fornecedores!A:B,2,0) -> SIMPLE ENERGY ASSESSORIA E GESTAO DE ENERGIA LTDA. | D30: Evandrea | E30: 00021352 | F30: 45810 | G30: 733.38 | H30: =VLOOKUP(E30&B30,'Conf Oracle'!A:F,6,0) -> 45817.478 | J30: =IF(OR(ISBLANK(F30), ISBLANK(H30)), "", IFERROR(NETWORKDAYS(F30, H30), "")) -> 6
A31: 45813 | B31: 15667402000111 | C31: =VLOOKUP(B31,Fornecedores!A:B,2,0) -> SIMPLE ENERGY ASSESSORIA E GESTAO DE ENERGIA LTDA. | D31: Evandrea | E31: 00021349 | F31: 45810 | G31: 733.38 | H31: =VLOOKUP(E31&B31,'Conf Oracle'!A:F,6,0) -> 45818.385 | J31: =IF(OR(ISBLANK(F31), ISBLANK(H31)), "", IFERROR(NETWORKDAYS(F31, H31), "")) -> 7
A32: 45813 | B32: 15667402000111 | C32: =VLOOKUP(B32,Fornecedores!A:B,2,0) -> SIMPLE ENERGY ASSESSORIA E GESTAO DE ENERGIA LTDA. | D32: Evandrea | E32: 00021345 | F32: 45810 | G32: 733.38 | H32: =VLOOKUP(E32&B32,'Conf Oracle'!A:F,6,0) -> 45817.469 | J32: =IF(OR(ISBLANK(F32), ISBLANK(H32)), "", IFERROR(NETWORKDAYS(F32, H32), "")) -> 6
A33: 45813 | B33: 00001180000126 | C33: =VLOOKUP(B33,Fornecedores!A:B,2,0) -> Centrais Elétricas Brasileiras S/A - Eletrobras | D33: Evandrea | E33: 00046995 | F33: 45811 | G33: 20868.07 | H33: =VLOOKUP(E33&B33,'Conf Oracle'!A:F,6,0) -> 45817.454 | J33: =IF(OR(ISBLANK(F33), ISBLANK(H33)), "", IFERROR(NETWORKDAYS(F33, H33), "")) -> 5
A34: 45813 | B34: 00001180000126 | C34: =VLOOKUP(B34,Fornecedores!A:B,2,0) -> Centrais Elétricas Brasileiras S/A - Eletrobras | D34: Evandrea | E34: 00046994 | F34: 45811 | G34: 39255.84 | H34: =VLOOKUP(E34&B34,'Conf Oracle'!A:F,6,0) -> 45817.457 | J34: =IF(OR(ISBLANK(F34), ISBLANK(H34)), "", IFERROR(NETWORKDAYS(F34, H34), "")) -> 5
A35: 45813 | B35: 00001180000126 | C35: =VLOOKUP(B35,Fornecedores!A:B,2,0) -> Centrais Elétricas Brasileiras S/A - Eletrobras | D35: Evandrea | E35: 00046993 | F35: 45811 | G35: 87307.77 | H35: =VLOOKUP(E35&B35,'Conf Oracle'!A:F,6,0) -> 45817.471 | J35: =IF(OR(ISBLANK(F35), ISBLANK(H35)), "", IFERROR(NETWORKDAYS(F35, H35), "")) -> 5
A36: 45813 | B36: 00001180000126 | C36: =VLOOKUP(B36,Fornecedores!A:B,2,0) -> Centrais Elétricas Brasileiras S/A - Eletrobras | D36: Evandrea | E36: 00046992 | F36: 45811 | G36: 59812.8 | H36: =VLOOKUP(E36&B36,'Conf Oracle'!A:F,6,0) -> 45817.447 | J36: =IF(OR(ISBLANK(F36), ISBLANK(H36)), "", IFERROR(NETWORKDAYS(F36, H36), "")) -> 5
A37: 45810 | B37: 01609514000101 | C37: =VLOOKUP(B37,Fornecedores!A:B,2,0) -> E-HUNTER TECNOLOGIA DA INFORMAÇÃO LTDA | D37: Sunara | E37: 00005473 | F37: 45810 | G37: 2614 | H37: =VLOOKUP(E37&B37,'Conf Oracle'!A:F,6,0) -> 45824.713 | J37: =IF(OR(ISBLANK(F37), ISBLANK(H37)), "", IFERROR(NETWORKDAYS(F37, H37), "")) -> 11
A38: 45813 | B38: 09162855000517 | C38: =VLOOKUP(B38,Fornecedores!A:B,2,0) -> PTLS SERV TECNOLOGIA E ASSESS TECN LTDA | D38: Sunara | E38: 00217323 | F38: 45810 | G38: 30803.59 | H38: =VLOOKUP(E38&B38,'Conf Oracle'!A:F,6,0) -> 45825.377 | J38: =IF(OR(ISBLANK(F38), ISBLANK(H38)), "", IFERROR(NETWORKDAYS(F38, H38), "")) -> 12
A39: 45813 | B39: 09162855000517 | C39: =VLOOKUP(B39,Fornecedores!A:B,2,0) -> PTLS SERV TECNOLOGIA E ASSESS TECN LTDA | D39: Sunara | E39: 00217322 | F39: 45810 | G39: 6363.07 | H39: =VLOOKUP(E39&B39,'Conf Oracle'!A:F,6,0) -> 45824.73 | J39: =IF(OR(ISBLANK(F39), ISBLANK(H39)), "", IFERROR(NETWORKDAYS(F39, H39), "")) -> 11
A40: 45814 | B40: 40432544010290 | C40: =VLOOKUP(B40,Fornecedores!A:B,2,0) -> CLARO SA | D40: Evandrea | E40: 55993182 | F40: 45812 | G40: 2205.53 | H40: 45831 | I40: lançada dia 23/06 | J40: =IF(OR(ISBLANK(F40), ISBLANK(H40)), "", IFERROR(NETWORKDAYS(F40, H40), "")) -> 14
A41: 45814 | B41: 40432544044004 | C41: =VLOOKUP(B41,Fornecedores!A:B,2,0) -> CLARO SA | D41: Evandrea | E41: 31199182 | F41: 45812 | G41: 3370.45 | H41: 45831 | I41: lançada dia 23/06 | J41: =IF(OR(ISBLANK(F41), ISBLANK(H41)), "", IFERROR(NETWORKDAYS(F41, H41), "")) -> 14
...

Sheet Controle de NF - Maio
A2: Mês | B2: CNPJ | C2: Fornecedor | D2: Gestor Adm | E2: NF | F2: Emissão da NF | G2: Valor da NF | H2: Conferência | I2: Observação | J2: SLA
A3: 45782 | B3: 16554325000156 | C3: =VLOOKUP(B3,Fornecedores!A:B,2,0) -> AMBIENTE VERDE RESIDUOS LTDA | D3: Evandrea | E3: 00000955 | F3: 45779 | G3: 2690 | H3: =VLOOKUP(E3&B3,'Conf Oracle'!A:F,6,0) -> 45789.363 | J3: =IF(OR(ISBLANK(F3), ISBLANK(H3)), "", IFERROR(NETWORKDAYS(F3, H3), "")) -> 7
A4: 45782 | B4: 15667402000111 | C4: =VLOOKUP(B4,Fornecedores!A:B,2,0) -> SIMPLE ENERGY ASSESSORIA E GESTAO DE ENERGIA LTDA. | D4: Evandrea | E4: 00020983 | F4: 45779 | G4: 733.38 | H4: =VLOOKUP(E4&B4,'Conf Oracle'!A:F,6,0) -> 45786.469 | J4: =IF(OR(ISBLANK(F4), ISBLANK(H4)), "", IFERROR(NETWORKDAYS(F4, H4), "")) -> 6
A5: 45782 | B5: 15667402000111 | C5: =VLOOKUP(B5,Fornecedores!A:B,2,0) -> SIMPLE ENERGY ASSESSORIA E GESTAO DE ENERGIA LTDA. | D5: Evandrea | E5: 00020987 | F5: 45779 | G5: 733.38 | H5: =VLOOKUP(E5&B5,'Conf Oracle'!A:F,6,0) -> 45786.463 | J5: =IF(OR(ISBLANK(F5), ISBLANK(H5)), "", IFERROR(NETWORKDAYS(F5, H5), "")) -> 6
A6: 45782 | B6: 15667402000111 | C6: =VLOOKUP(B6,Fornecedores!A:B,2,0) -> SIMPLE ENERGY ASSESSORIA E GESTAO DE ENERGIA LTDA. | D6: Evandrea | E6: 00020976 | F6: 45779 | G6: 733.38 | H6: =VLOOKUP(E6&B6,'Conf Oracle'!A:F,6,0) -> 45786.461 | J6: =IF(OR(ISBLANK(F6), ISBLANK(H6)), "", IFERROR(NETWORKDAYS(F6, H6), "")) -> 6
A7: 45782 | B7: 15667402000111 | C7: =VLOOKUP(B7,Fornecedores!A:B,2,0) -> SIMPLE ENERGY ASSESSORIA E GESTAO DE ENERGIA LTDA. | D7: Evandrea | E7: 00020972 | F7: 45779 | G7: 733.38 | H7: =VLOOKUP(E7&B7,'Conf Oracle'!A:F,6,0) -> 45786.472 | J7: =IF(OR(ISBLANK(F7), ISBLANK(H7)), "", IFERROR(NETWORKDAYS(F7, H7), "")) -> 6
A8: 45783 | B8: 90347840005691 | C8: =VLOOKUP(B8,Fornecedores!A:B,2,0) -> TK ELEVADORES BRASIL LTDA. | D8: Evandrea | E8: 00111804 | F8: 45779 | G8: 13781.17 | H8: =VLOOKUP(E8&B8,'Conf Oracle'!A:F,6,0) -> 45786.465 | J8: =IF(OR(ISBLANK(F8), ISBLANK(H8)), "", IFERROR(NETWORKDAYS(F8, H8), "")) -> 6
A9: 45783 | B9: 00001180000126 | C9: =VLOOKUP(B9,Fornecedores!A:B,2,0) -> Centrais Elétricas Brasileiras S/A - Eletrobras | D9: Evandrea | E9: 00041021 | F9: 45782 | G9: 88432.31 | H9: =VLOOKUP(E9&B9,'Conf Oracle'!A:F,6,0) -> 45786.542 | J9: =IF(OR(ISBLANK(F9), ISBLANK(H9)), "", IFERROR(NETWORKDAYS(F9, H9), "")) -> 5
A10: 45783 | B10: 00001180000126 | C10: =VLOOKUP(B10,Fornecedores!A:B,2,0) -> Centrais Elétricas Brasileiras S/A - Eletrobras | D10: Evandrea | E10: 00041024 | F10: 45782 | G10: 41841.42 | H10: =VLOOKUP(E10&B10,'Conf Oracle'!A:F,6,0) -> 45786.537 | J10: =IF(OR(ISBLANK(F10), ISBLANK(H10)), "", IFERROR(NETWORKDAYS(F10, H10), "")) -> 5
A11: 45783 | B11: 00001180000126 | C11: =VLOOKUP(B11,Fornecedores!A:B,2,0) -> Centrais Elétricas Brasileiras S/A - Eletrobras | D11: Evandrea | E11: 00041020 | F11: 45782 | G11: 64408.65 | H11: =VLOOKUP(E11&B11,'Conf Oracle'!A:F,6,0) -> 45786.546 | J11: =IF(OR(ISBLANK(F11), ISBLANK(H11)), "", IFERROR(NETWORKDAYS(F11, H11), "")) -> 5
A12: 45783 | B12: 00001180000126 | C12: =VLOOKUP(B12,Fornecedores!A:B,2,0) -> Centrais Elétricas Brasileiras S/A - Eletrobras | D12: Evandrea | E12: 00041025 | F12: 45782 | G12: 21403.99 | H12: =VLOOKUP(E12&B12,'Conf Oracle'!A:F,6,0) -> 45786.534 | J12: =IF(OR(ISBLANK(F12), ISBLANK(H12)), "", IFERROR(NETWORKDAYS(F12, H12), "")) -> 5
A13: 45783 | B13: 00028986001694 | C13: =VLOOKUP(B13,Fornecedores!A:B,2,0) -> ELEVADORES ATLAS SCHINDLER SA | D13: Evandrea | E13: 00468657 | F13: 45782 | G13: 1960.94 | H13: =VLOOKUP(E13&B13,'Conf Oracle'!A:F,6,0) -> 45796.454 | I13: LANÇADA | J13: =IF(OR(ISBLANK(F13), ISBLANK(H13)), "", IFERROR(NETWORKDAYS(F13, H13), "")) -> 11
A14: 45783 | B14: 08270682000164 | C14: =VLOOKUP(B14,Fornecedores!A:B,2,0) -> CONFIDERE IMOBILIARIA LTDA | D14: Evandrea | E14: 00202505 | F14: 45784 | G14: 2970031.4 | H14: 45789 | J14: =IF(OR(ISBLANK(F14), ISBLANK(H14)), "", IFERROR(NETWORKDAYS(F14, H14), "")) -> 4
A15: 45783 | B15: 72381189000110 | C15: =VLOOKUP(B15,Fornecedores!A:B,2,0) -> DELL COMPUTADORES DO BRASIL LTDA | D15: Guilherme | E15: 02724579 | F15: 45779 | G15: 56100.02 | H15: =VLOOKUP(E15&B15,'Conf Oracle'!A:F,6,0) -> 45798.65 | I15: LANÇADA | J15: =IF(OR(ISBLANK(F15), ISBLANK(H15)), "", IFERROR(NETWORKDAYS(F15, H15), "")) -> 14
A16: 45783 | B16: 72381189000110 | C16: =VLOOKUP(B16,Fornecedores!A:B,2,0) -> DELL COMPUTADORES DO BRASIL LTDA | D16: Guilherme | E16: 02724573 | F16: 45779 | G16: 14999.99 | H16: =VLOOKUP(E16&B16,'Conf Oracle'!A:F,6,0) -> 45798.65 | J16: =IF(OR(ISBLANK(F16), ISBLANK(H16)), "", IFERROR(NETWORKDAYS(F16, H16), "")) -> 14
A17: 45783 | B17: 72381189000110 | C17: =VLOOKUP(B17,Fornecedores!A:B,2,0) -> DELL COMPUTADORES DO BRASIL LTDA | D17: Guilherme | E17: 02724575 | F17: 45779 | G17: 104399.97 | H17: =VLOOKUP(E17&B17,'Conf Oracle'!A:F,6,0) -> 45798.634 | J17: =IF(OR(ISBLANK(F17), ISBLANK(H17)), "", IFERROR(NETWORKDAYS(F17, H17), "")) -> 14
A18: 45783 | B18: 72381189000110 | C18: =VLOOKUP(B18,Fornecedores!A:B,2,0) -> DELL COMPUTADORES DO BRASIL LTDA | D18: Guilherme | E18: 02724579 | F18: 45779 | G18: 56100.02 | H18: =VLOOKUP(E18&B18,'Conf Oracle'!A:F,6,0) -> 45798.65 | J18: =IF(OR(ISBLANK(F18), ISBLANK(H18)), "", IFERROR(NETWORKDAYS(F18, H18), "")) -> 14
A19: 45785 | B19: 72381189001001 | C19: =VLOOKUP(B19,Fornecedores!A:B,2,0) -> DELL COMPUTADORES DO BRASIL LTDA | D19: Guilherme | E19: 07619304 | F19: 45783 | G19: 192271.61 | H19: =VLOOKUP(E19&B19,'Conf Oracle'!A:F,6,0) -> 45804.632 | J19: =IF(OR(ISBLANK(F19), ISBLANK(H19)), "", IFERROR(NETWORKDAYS(F19, H19), "")) -> 16
A20: 45785 | B20: 72381189001001 | C20: =VLOOKUP(B20,Fornecedores!A:B,2,0) -> DELL COMPUTADORES DO BRASIL LTDA | D20: Guilherme | E20: 02726713 | F20: 45783 | G20: 59347.4 | H20: =VLOOKUP(E20&B20,'Conf Oracle'!A:F,6,0) -> 45804.674 | J20: =IF(OR(ISBLANK(F20), ISBLANK(H20)), "", IFERROR(NETWORKDAYS(F20, H20), "")) -> 16
A21: 45785 | B21: 72381189001001 | C21: =VLOOKUP(B21,Fornecedores!A:B,2,0) -> DELL COMPUTADORES DO BRASIL LTDA | D21: Guilherme | E21: 07621804 | F21: 45784 | G21: 123667.75 | H21: =VLOOKUP(E21&B21,'Conf Oracle'!A:F,6,0) -> 45803.562 | J21: =IF(OR(ISBLANK(F21), ISBLANK(H21)), "", IFERROR(NETWORKDAYS(F21, H21), "")) -> 14
A22: 45785 | B22: 72381189001001 | C22: =VLOOKUP(B22,Fornecedores!A:B,2,0) -> DELL COMPUTADORES DO BRASIL LTDA | D22: Guilherme | E22: 07621796 | F22: 45784 | G22: 140004.35 | H22: =VLOOKUP(E22&B22,'Conf Oracle'!A:F,6,0) -> 45799.65 | J22: =IF(OR(ISBLANK(F22), ISBLANK(H22)), "", IFERROR(NETWORKDAYS(F22, H22), "")) -> 12
A23: 45785 | B23: 72381189001001 | C23: =VLOOKUP(B23,Fornecedores!A:B,2,0) -> DELL COMPUTADORES DO BRASIL LTDA | D23: Guilherme | E23: 02727291 | F23: 45784 | G23: 90866.9 | H23: =VLOOKUP(E23&B23,'Conf Oracle'!A:F,6,0) -> 45803.493 | J23: =IF(OR(ISBLANK(F23), ISBLANK(H23)), "", IFERROR(NETWORKDAYS(F23, H23), "")) -> 14
A24: 45785 | B24: 72381189001001 | C24: =VLOOKUP(B24,Fornecedores!A:B,2,0) -> DELL COMPUTADORES DO BRASIL LTDA | D24: Guilherme | E24: 02727290 | F24: 45784 | G24: 41258.43 | H24: =VLOOKUP(E24&B24,'Conf Oracle'!A:F,6,0) -> 45805.438 | J24: =IF(OR(ISBLANK(F24), ISBLANK(H24)), "", IFERROR(NETWORKDAYS(F24, H24), "")) -> 16
A25: 45785 | B25: 72381189001001 | C25: =VLOOKUP(B25,Fornecedores!A:B,2,0) -> DELL COMPUTADORES DO BRASIL LTDA | D25: Guilherme | E25: 02727292 | F25: 45784 | G25: 49112.05 | H25: =VLOOKUP(E25&B25,'Conf Oracle'!A:F,6,0) -> 45803.478 | J25: =IF(OR(ISBLANK(F25), ISBLANK(H25)), "", IFERROR(NETWORKDAYS(F25, H25), "")) -> 14
A26: 45785 | B26: 72381189001001 | C26: =VLOOKUP(B26,Fornecedores!A:B,2,0) -> DELL COMPUTADORES DO BRASIL LTDA | D26: Guilherme | E26: 07621797 | F26: 45784 | G26: 255168.33 | H26: =VLOOKUP(E26&B26,'Conf Oracle'!A:F,6,0) -> 45804.666 | J26: =IF(OR(ISBLANK(F26), ISBLANK(H26)), "", IFERROR(NETWORKDAYS(F26, H26), "")) -> 15
A27: 45785 | B27: 35808969000178 | C27: =VLOOKUP(B27,Fornecedores!A:B,2,0) -> DIGITAL 8 SOLUCOES DIGITAIS LTDA | D27: Guilherme | E27: 00000284 | F27: 45785 | G27: 26138.11 | H27: CANCELADA | I27: NF CANCELADA | J27: =IF(OR(ISBLANK(F27), ISBLANK(H27)), "", IFERROR(NETWORKDAYS(F27, H27), ""))
A28: 45782 | B28: 58652678000139 | C28: =VLOOKUP(B28,Fornecedores!A:B,2,0) -> COLUMBIA STORAGE INTEGR DE SITEMAS LTDA | D28: Ingrid | E28: 00011125 | F28: 45779 | G28: 17116.41 | H28: =VLOOKUP(E28&B28,'Conf Oracle'!A:F,6,0) -> 45799.428 | J28: =IF(OR(ISBLANK(F28), ISBLANK(H28)), "", IFERROR(NETWORKDAYS(F28, H28), "")) -> 15
A29: 45782 | B29: 23412247000110 | C29: =VLOOKUP(B29,Fornecedores!A:B,2,0) -> AMAZON AWS SERVICOS BRASIL LTDA | D29: Ingrid | E29: 04299709 | F29: 45779 | G29: 545976.71 | H29: =VLOOKUP(E29&B29,'Conf Oracle'!A:F,6,0) -> 45806.543 | J29: =IF(OR(ISBLANK(F29), ISBLANK(H29)), "", IFERROR(NETWORKDAYS(F29, H29), "")) -> 20
A30: 45782 | B30: 23412247000110 | C30: =VLOOKUP(B30,Fornecedores!A:B,2,0) -> AMAZON AWS SERVICOS BRASIL LTDA | D30: Ingrid | E30: 04299227 | F30: 45779 | G30: 59766.48 | H30: =VLOOKUP(E30&B30,'Conf Oracle'!A:F,6,0) -> 45806.54 | J30: =IF(OR(ISBLANK(F30), ISBLANK(H30)), "", IFERROR(NETWORKDAYS(F30, H30), "")) -> 20
